Traceback (most recent call last):
  File "/Users/pennrobotics/Southmoon/init.py", line 38, in <module>
    local_config_source.update(config)
  File "/Users/pennrobotics/Southmoon/config/ConfigSource.py", line 29, in update
    with open(self._config_filename, "r") as config_file:
         ^^^^^^^^^^^^^^^^^^^^^^^^^^^^^^^^
FileNotFoundError: [Errno 2] No such file or directory: '/Users/pennrobotics/Southmoon/setup/config_rightCam.json'
Traceback (most recent call last):
  File "/Users/pennrobotics/Southmoon/init.py", line 38, in <module>
Traceback (most recent call last):
  File "/Users/pennrobotics/Southmoon/init.py", line 38, in <module>
    local_config_source.update(config)
  File "/Users/pennrobotics/Southmoon/config/ConfigSource.py", line 29, in update
    local_config_source.update(config)
    with open(self._config_filename, "r") as config_file:
  File "/Users/pennrobotics/Southmoon/config/ConfigSource.py", line 29, in update
         ^^^^^^^^^^^^^^^^^^^^^^^^^^^^^^^^
FileNotFoundError: [Errno 2] No such file or directory: '/Users/pennrobotics/Southmoon/setup/config_extraFrontCam.json'
    with open(self._config_filename, "r") as config_file:
         ^^^^^^^^^^^^^^^^^^^^^^^^^^^^^^^^
FileNotFoundError: [Errno 2] No such file or directory: '/Users/pennrobotics/Southmoon/setup/config_backCam.json'
Traceback (most recent call last):
  File "/Users/pennrobotics/Southmoon/init.py", line 67, in <module>
    ntcore.NetworkTableInstance.getDefault().startClient4(config.local_config.device_id)
TypeError: startClient4(): incompatible function arguments. The following argument types are supported:
    1. (self: ntcore._ntcore.NetworkTableInstance, identity: str) -> None

Invoked with: <ntcore._ntcore.NetworkTableInstance object at 0x122752170>, 1
Traceback (most recent call last):
  File "/Users/pennrobotics/Southmoon/init.py", line 38, in <module>
    local_config_source.update(config)
  File "/Users/pennrobotics/Southmoon/config/ConfigSource.py", line 29, in update
    with open(self._config_filename, "r") as config_file:
         ^^^^^^^^^^^^^^^^^^^^^^^^^^^^^^^^
FileNotFoundError: [Errno 2] No such file or directory: '/Users/pennrobotics/Southmoon/setup/config_rightCam.json'
Traceback (most recent call last):
  File "/Users/pennrobotics/Southmoon/init.py", line 38, in <module>
    local_config_source.update(config)
  File "/Users/pennrobotics/Southmoon/config/ConfigSource.py", line 29, in update
    with open(self._config_filename, "r") as config_file:
         ^^^^^^^^^^^^^^^^^^^^^^^^^^^^^^^^
FileNotFoundError: [Errno 2] No such file or directory: '/Users/pennrobotics/Southmoon/setup/config_backCam.json'
Traceback (most recent call last):
  File "/Users/pennrobotics/Southmoon/init.py", line 38, in <module>
    local_config_source.update(config)
  File "/Users/pennrobotics/Southmoon/config/ConfigSource.py", line 29, in update
    with open(self._config_filename, "r") as config_file:
         ^^^^^^^^^^^^^^^^^^^^^^^^^^^^^^^^
FileNotFoundError: [Errno 2] No such file or directory: '/Users/pennrobotics/Southmoon/setup/config_extraFrontCam.json'
Traceback (most recent call last):
  File "/Users/pennrobotics/Southmoon/init.py", line 81, in <module>
    remote_config_source.update(config)
  File "/Users/pennrobotics/Southmoon/config/ConfigSource.py", line 95, in update
    self._camera_id_sub = nt_table.getStringTopic("camera_id").subscribe(RemoteConfig.camera_id)
                          ^^^^^^^^^^^^^^^^^^^^^^^^^^^^^^^^^^^^^^^^^^^^^^^^^^^^^^^^^^^^^^^^^^^^^^
TypeError: subscribe(): incompatible function arguments. The following argument types are supported:
    1. (self: ntcore._ntcore.StringTopic, defaultValue: str, options: ntcore._ntcore.PubSubOptions = <ntcore._ntcore.PubSubOptions object at 0x1008dd9f0>) -> ntcore._ntcore.StringSubscriber

Invoked with: <ntcore._ntcore.StringTopic object at 0x111491d30>, 0
Traceback (most recent call last):
  File "/Users/pennrobotics/Southmoon/init.py", line 38, in <module>
    local_config_source.update(config)
  File "/Users/pennrobotics/Southmoon/config/ConfigSource.py", line 29, in update
Traceback (most recent call last):
    with open(self._config_filename, "r") as config_file:
  File "/Users/pennrobotics/Southmoon/init.py", line 38, in <module>
         ^^^^^^^^^^^^^^^^^^^^^^^^^^^^^^^^
FileNotFoundError: [Errno 2] No such file or directory: '/Users/pennrobotics/Southmoon/setup/config_backCam.json'
    local_config_source.update(config)
  File "/Users/pennrobotics/Southmoon/config/ConfigSource.py", line 29, in update
Traceback (most recent call last):
  File "/Users/pennrobotics/Southmoon/init.py", line 38, in <module>
    with open(self._config_filename, "r") as config_file:
         ^^^^^^^^^^^^^^^^^^^^^^^^^^^^^^^^
FileNotFoundError: [Errno 2] No such file or directory: '/Users/pennrobotics/Southmoon/setup/config_rightCam.json'
    local_config_source.update(config)
  File "/Users/pennrobotics/Southmoon/config/ConfigSource.py", line 29, in update
    with open(self._config_filename, "r") as config_file:
         ^^^^^^^^^^^^^^^^^^^^^^^^^^^^^^^^
FileNotFoundError: [Errno 2] No such file or directory: '/Users/pennrobotics/Southmoon/setup/config_extraFrontCam.json'
Traceback (most recent call last):
  File "/Users/pennrobotics/Southmoon/init.py", line 81, in <module>
    remote_config_source.update(config)
  File "/Users/pennrobotics/Southmoon/config/ConfigSource.py", line 95, in update
    self._camera_id_sub = nt_table.getIntegerTopic("camera_id").subscribe(str(RemoteConfig.camera_id))
                          ^^^^^^^^^^^^^^^^^^^^^^^^^^^^^^^^^^^^^^^^^^^^^^^^^^^^^^^^^^^^^^^^^^^^^^^^^^^^
TypeError: subscribe(): incompatible function arguments. The following argument types are supported:
    1. (self: ntcore._ntcore.IntegerTopic, defaultValue: int, options: ntcore._ntcore.PubSubOptions = <ntcore._ntcore.PubSubOptions object at 0x102865c70>) -> ntcore._ntcore.IntegerSubscriber

Invoked with: <ntcore._ntcore.IntegerTopic object at 0x12224bbb0>, '0'
Traceback (most recent call last):
  File "/Users/pennrobotics/Southmoon/init.py", line 38, in <module>
    local_config_source.update(config)
  File "/Users/pennrobotics/Southmoon/config/ConfigSource.py", line 29, in update
    with open(self._config_filename, "r") as config_file:
         ^^^^^^^^^^^^^^^^^^^^^^^^^^^^^^^^
FileNotFoundError: [Errno 2] No such file or directory: '/Users/pennrobotics/Southmoon/setup/config_backCam.json'
Traceback (most recent call last):
  File "/Users/pennrobotics/Southmoon/init.py", line 38, in <module>
    local_config_source.update(config)
  File "/Users/pennrobotics/Southmoon/config/ConfigSource.py", line 29, in update
    with open(self._config_filename, "r") as config_file:
         ^^^^^^^^^^^^^^^^^^^^^^^^^^^^^^^^
FileNotFoundError: [Errno 2] No such file or directory: '/Users/pennrobotics/Southmoon/setup/config_extraFrontCam.json'
Traceback (most recent call last):
  File "/Users/pennrobotics/Southmoon/init.py", line 38, in <module>
    local_config_source.update(config)
  File "/Users/pennrobotics/Southmoon/config/ConfigSource.py", line 29, in update
    with open(self._config_filename, "r") as config_file:
         ^^^^^^^^^^^^^^^^^^^^^^^^^^^^^^^^
FileNotFoundError: [Errno 2] No such file or directory: '/Users/pennrobotics/Southmoon/setup/config_rightCam.json'
OpenCV: not authorized to capture video (status 0), requesting...
OpenCV: camera failed to properly initialize!
[ WARN:0@0.722] global cap.cpp:323 open VIDEOIO(OBSENSOR): raised unknown C++ exception!


Traceback (most recent call last):
Traceback (most recent call last):
  File "/Users/pennrobotics/Southmoon/init.py", line 38, in <module>
  File "/Users/pennrobotics/Southmoon/init.py", line 38, in <module>
Traceback (most recent call last):
    local_config_source.update(config)
    local_config_source.update(config)
  File "/Users/pennrobotics/Southmoon/init.py", line 38, in <module>
  File "/Users/pennrobotics/Southmoon/config/ConfigSource.py", line 29, in update
  File "/Users/pennrobotics/Southmoon/config/ConfigSource.py", line 29, in update
    local_config_source.update(config)
    with open(self._config_filename, "r") as config_file:
    with open(self._config_filename, "r") as config_file:
  File "/Users/pennrobotics/Southmoon/config/ConfigSource.py", line 29, in update
         ^^^^^^^^^^^^^^^^^^^^^^^^^^^^^^^^
         ^^^^^^^^^^^^^^^^^^^^^^^^^^^^^^^^
FileNotFoundError: [Errno 2] No such file or directory: '/Users/pennrobotics/Southmoon/setup/config_rightCam.json'
FileNotFoundError: [Errno 2] No such file or directory: '/Users/pennrobotics/Southmoon/setup/config_extraFrontCam.json'
    with open(self._config_filename, "r") as config_file:
         ^^^^^^^^^^^^^^^^^^^^^^^^^^^^^^^^
FileNotFoundError: [Errno 2] No such file or directory: '/Users/pennrobotics/Southmoon/setup/config_backCam.json'
OpenCV: not authorized to capture video (status 0), requesting...
OpenCV: camera failed to properly initialize!
[ WARN:0@0.720] global cap.cpp:323 open VIDEOIO(OBSENSOR): raised unknown C++ exception!


Traceback (most recent call last):
  File "/Users/pennrobotics/Southmoon/init.py", line 38, in <module>
Traceback (most recent call last):
  File "/Users/pennrobotics/Southmoon/init.py", line 38, in <module>
    local_config_source.update(config)
  File "/Users/pennrobotics/Southmoon/config/ConfigSource.py", line 29, in update
Traceback (most recent call last):
    local_config_source.update(config)
  File "/Users/pennrobotics/Southmoon/init.py", line 38, in <module>
  File "/Users/pennrobotics/Southmoon/config/ConfigSource.py", line 29, in update
    with open(self._config_filename, "r") as config_file:
         ^^^^^^^^^^^^^^^^^^^^^^^^^^^^^^^^
FileNotFoundError: [Errno 2] No such file or directory: '/Users/pennrobotics/Southmoon/setup/config_rightCam.json'
    with open(self._config_filename, "r") as config_file:
    local_config_source.update(config)
         ^^^^^^^^^^^^^^^^^^^^^^^^^^^^^^^^
FileNotFoundError: [Errno 2] No such file or directory: '/Users/pennrobotics/Southmoon/setup/config_extraFrontCam.json'
  File "/Users/pennrobotics/Southmoon/config/ConfigSource.py", line 29, in update
    with open(self._config_filename, "r") as config_file:
         ^^^^^^^^^^^^^^^^^^^^^^^^^^^^^^^^
FileNotFoundError: [Errno 2] No such file or directory: '/Users/pennrobotics/Southmoon/setup/config_backCam.json'
Traceback (most recent call last):
Traceback (most recent call last):
  File "/Users/pennrobotics/Southmoon/init.py", line 38, in <module>
  File "/Users/pennrobotics/Southmoon/init.py", line 38, in <module>
Traceback (most recent call last):
  File "/Users/pennrobotics/Southmoon/init.py", line 38, in <module>
    local_config_source.update(config)
    local_config_source.update(config)
    local_config_source.update(config)
  File "/Users/pennrobotics/Southmoon/config/ConfigSource.py", line 29, in update
  File "/Users/pennrobotics/Southmoon/config/ConfigSource.py", line 29, in update
  File "/Users/pennrobotics/Southmoon/config/ConfigSource.py", line 29, in update
    with open(self._config_filename, "r") as config_file:
    with open(self._config_filename, "r") as config_file:
    with open(self._config_filename, "r") as config_file:
         ^^^^^^^^^^^^^^^^^^^^^^^^^^^^^^^^
         ^^^^^^^^^^^^^^^^^^^^^^^^^^^^^^^^
         ^^^^^^^^^^^^^^^^^^^^^^^^^^^^^^^^
FileNotFoundError: [Errno 2] No such file or directory: '/Users/pennrobotics/Southmoon/setup/config_backCam.json'
FileNotFoundError: [Errno 2] No such file or directory: '/Users/pennrobotics/Southmoon/setup/config_rightCam.json'
FileNotFoundError: [Errno 2] No such file or directory: '/Users/pennrobotics/Southmoon/setup/config_extraFrontCam.json'
Traceback (most recent call last):
Traceback (most recent call last):
Traceback (most recent call last):
  File "/Users/pennrobotics/Southmoon/init.py", line 38, in <module>
  File "/Users/pennrobotics/Southmoon/init.py", line 38, in <module>
  File "/Users/pennrobotics/Southmoon/init.py", line 38, in <module>
    local_config_source.update(config)
    local_config_source.update(config)
    local_config_source.update(config)
  File "/Users/pennrobotics/Southmoon/config/ConfigSource.py", line 29, in update
  File "/Users/pennrobotics/Southmoon/config/ConfigSource.py", line 29, in update
  File "/Users/pennrobotics/Southmoon/config/ConfigSource.py", line 29, in update
    with open(self._config_filename, "r") as config_file:
    with open(self._config_filename, "r") as config_file:
         ^^^^^^^^^^^^^^^^^^^^^^^^^^^^^^^^
    with open(self._config_filename, "r") as config_file:
FileNotFoundError: [Errno 2] No such file or directory: '/Users/pennrobotics/Southmoon/setup/config_extraFrontCam.json'
         ^^^^^^^^^^^^^^^^^^^^^^^^^^^^^^^^
         ^^^^^^^^^^^^^^^^^^^^^^^^^^^^^^^^
FileNotFoundError: [Errno 2] No such file or directory: '/Users/pennrobotics/Southmoon/setup/config_backCam.json'
FileNotFoundError: [Errno 2] No such file or directory: '/Users/pennrobotics/Southmoon/setup/config_rightCam.json'
Traceback (most recent call last):
  File "/Users/pennrobotics/Southmoon/init.py", line 38, in <module>
Traceback (most recent call last):
Traceback (most recent call last):
  File "/Users/pennrobotics/Southmoon/init.py", line 38, in <module>
  File "/Users/pennrobotics/Southmoon/init.py", line 38, in <module>
    local_config_source.update(config)
  File "/Users/pennrobotics/Southmoon/config/ConfigSource.py", line 29, in update
    local_config_source.update(config)
    local_config_source.update(config)
  File "/Users/pennrobotics/Southmoon/config/ConfigSource.py", line 29, in update
  File "/Users/pennrobotics/Southmoon/config/ConfigSource.py", line 29, in update
    with open(self._config_filename, "r") as config_file:
         ^^^^^^^^^^^^^^^^^^^^^^^^^^^^^^^^
    with open(self._config_filename, "r") as config_file:
FileNotFoundError: [Errno 2] No such file or directory: '/Users/pennrobotics/Southmoon/setup/config_extraFrontCam.json'
    with open(self._config_filename, "r") as config_file:
         ^^^^^^^^^^^^^^^^^^^^^^^^^^^^^^^^
FileNotFoundError: [Errno 2] No such file or directory: '/Users/pennrobotics/Southmoon/setup/config_backCam.json'
         ^^^^^^^^^^^^^^^^^^^^^^^^^^^^^^^^
FileNotFoundError: [Errno 2] No such file or directory: '/Users/pennrobotics/Southmoon/setup/config_rightCam.json'
Traceback (most recent call last):
  File "/Users/pennrobotics/Southmoon/init.py", line 38, in <module>
Traceback (most recent call last):
  File "/Users/pennrobotics/Southmoon/init.py", line 38, in <module>
    local_config_source.update(config)
    local_config_source.update(config)
Traceback (most recent call last):
  File "/Users/pennrobotics/Southmoon/config/ConfigSource.py", line 29, in update
  File "/Users/pennrobotics/Southmoon/config/ConfigSource.py", line 29, in update
  File "/Users/pennrobotics/Southmoon/init.py", line 38, in <module>
    with open(self._config_filename, "r") as config_file:
    with open(self._config_filename, "r") as config_file:
         ^^^^^^^^^^^^^^^^^^^^^^^^^^^^^^^^
FileNotFoundError: [Errno 2] No such file or directory: '/Users/pennrobotics/Southmoon/setup/config_extraFrontCam.json'
         ^^^^^^^^^^^^^^^^^^^^^^^^^^^^^^^^
    local_config_source.update(config)
FileNotFoundError: [Errno 2] No such file or directory: '/Users/pennrobotics/Southmoon/setup/config_backCam.json'
  File "/Users/pennrobotics/Southmoon/config/ConfigSource.py", line 29, in update
    with open(self._config_filename, "r") as config_file:
         ^^^^^^^^^^^^^^^^^^^^^^^^^^^^^^^^
FileNotFoundError: [Errno 2] No such file or directory: '/Users/pennrobotics/Southmoon/setup/config_rightCam.json'
